Workbook

Sheet Saisie actif
C1: Raison sociale
C2: NIF
C3: Source
C4: ACTIF | D4: Nature bilan | G4: Nature bilan | J4: Nature bilan | M4: Nature bilan | P4: Nature bilan
D5: Fiscal | G5: Fiscal | J5: Fiscal | M5: Fiscal | P5: Fiscal
D6: Date d'arrêté (N-4) | G6: Date d'arrêté (N-3) | J6: Date d'arrêté (N-2) | M6: Date d'arrêté (N-1) | P6: Date d'arrêté (N)
D8: Montants Bruts (KDZD) | E8: Amortissements, provisions et pertes de valeurs (KDZD) | F8: Net (KDZD) | G8: Montants Bruts (KDZD) | H8: Amortissements, provisions et pertes de valeurs (KDZD) | I8: Net (KDZD) | J8: Montants Bruts (KDZD) | K8: Amortissements, provisions et pertes de valeurs (KDZD) | L8: Net (KDZD) | M8: Montants Bruts (KDZD) | N8: Amortissements, provisions et pertes de valeurs (KDZD) | O8: Net (KDZD) | P8: Montants Bruts (KDZD) | Q8: Amortissements, provisions et pertes de valeurs (KDZD) | R8: Net (KDZD)
C9: ACTIFS NON COURANTS | D9: =+D11+D12+D17+D18+D10 -> 98524.757 | E9: =+E11+E12+E17+E18+E10 -> 38132.173 | F9: =+F11+F12+F17+F18+F10 -> 60392.584 | G9: =+G11+G12+G17+G18+G10 -> 98524.757 | H9: =+H11+H12+H17+H18+H10 -> 38132.173 | I9: =+I11+I12+I17+I18+I10 -> 60392.584 | J9: =+J11+J12+J17+J18+J10 -> 98524.757 | K9: =+K11+K12+K17+K18+K10 -> 38132.173 | ... R9: =+R11+R12+R17+R18+R10 -> 49709.866
C10: Ecart d’acquisition – goodwill positif ou négatif | F10: =+D10-E10 -> 0 | I10: =+G10-H10 -> 0 | L10: =+J10-K10 -> 0 | O10: =+M10-N10 -> 0 | R10: =+P10-Q10 -> 0
C11: Immobilisations incorporelles | D11: 1670 | E11: 775.501 | F11: =+D11-E11 -> 894.499 | G11: 1670 | H11: 775.501 | I11: =+G11-H11 -> 894.499 | J11: 1670 | K11: 775.501 | L11: =+J11-K11 -> 894.499 | M11: 1520 | N11: 459 | O11: =+M11-N11 -> 1061 | P11: 1520 | Q11: 459 | R11: =+P11-Q11 -> 1061
C12: Immobilisations corporelles | D12: =SUM(D13:D16) -> 96854.757 | E12: =SUM(E13:E16) -> 37356.672 | F12: =SUM(F13:F16) -> 59498.085 | G12: =SUM(G13:G16) -> 96854.757 | H12: =SUM(H13:H16) -> 37356.672 | I12: =SUM(I13:I16) -> 59498.085 | J12: =SUM(J13:J16) -> 96854.757 | K12: =SUM(K13:K16) -> 37356.672 | ... R12: =SUM(R13:R16) -> 48648.866
C13: Terrains | F13: =+D13-E13 -> 0 | I13: =+G13-H13 -> 0 | L13: =+J13-K13 -> 0 | O13: =+M13-N13 -> 0 | R13: =+P13-Q13 -> 0
C14: Bâtiments | D14: 6000 | E14: 925 | F14: =+D14-E14 -> 5075 | G14: 6000 | H14: 925 | I14: =+G14-H14 -> 5075 | J14: 6000 | K14: 925 | L14: =+J14-K14 -> 5075 | M14: 6000 | N14: 775 | O14: =+M14-N14 -> 5225 | P14: 6000 | Q14: 775 | R14: =+P14-Q14 -> 5225
C15: Autres immobilisations corporelles | D15: 90854.757 | E15: 36431.672 | F15: =+D15-E15 -> 54423.085 | G15: 90854.757 | H15: 36431.672 | I15: =+G15-H15 -> 54423.085 | J15: 90854.757 | K15: 36431.672 | L15: =+J15-K15 -> 54423.085 | M15: 71268.03 | N15: 27844.164 | O15: =+M15-N15 -> 43423.866 | P15: 71268.03 | Q15: 27844.164 | R15: =+P15-Q15 -> 43423.866
C16: Immobilisations en concession | F16: =+D16-E16 -> 0 | I16: =+G16-H16 -> 0 | L16: =+J16-K16 -> 0 | O16: =+M16-N16 -> 0 | R16: =+P16-Q16 -> 0
C17: Immobilisations en cours | F17: =+D17-E17 -> 0 | I17: =+G17-H17 -> 0 | L17: =+J17-K17 -> 0 | O17: =+M17-N17 -> 0 | R17: =+P17-Q17 -> 0
C18: Immobilisations financières | D18: =SUM(D19:D23) -> 0 | E18: =SUM(E19:E23) -> 0 | F18: =SUM(F19:F23) -> 0 | G18: =SUM(G19:G23) -> 0 | H18: =SUM(H19:H23) -> 0 | I18: =SUM(I19:I23) -> 0 | J18: =SUM(J19:J23) -> 0 | K18: =SUM(K19:K23) -> 0 | ... R18: =SUM(R19:R23) -> 0
C19: Titres mis en équivalence | F19: =+D19-E19 -> 0 | I19: =+G19-H19 -> 0 | L19: =+J19-K19 -> 0 | O19: =+M19-N19 -> 0 | R19: =+P19-Q19 -> 0
C20: Autres participations et créances rattachées | F20: =+D20-E20 -> 0 | I20: =+G20-H20 -> 0 | L20: =+J20-K20 -> 0 | O20: =+M20-N20 -> 0 | R20: =+P20-Q20 -> 0
C21: Autres titres immobilisés | F21: =+D21-E21 -> 0 | I21: =+G21-H21 -> 0 | L21: =+J21-K21 -> 0 | O21: =+M21-N21 -> 0 | R21: =+P21-Q21 -> 0
C22: Prêts et autres actifs financiers non courants | F22: =+D22-E22 -> 0 | I22: =+G22-H22 -> 0 | L22: =+J22-K22 -> 0 | O22: =+M22-N22 -> 0 | R22: =+P22-Q22 -> 0
C23: Impôts différés actif | F23: =+D23-E23 -> 0 | I23: =+G23-H23 -> 0 | L23: =+J23-K23 -> 0 | O23: =+M23-N23 -> 0 | R23: =+P23-Q23 -> 0
C24: TOTAL ACTIF NON COURANT | D24: =+D9 -> 98524.757 | E24: =+E9 -> 38132.173 | F24: =+F9 -> 60392.584 | G24: =+G9 -> 98524.757 | H24: =+H9 -> 38132.173 | I24: =+I9 -> 60392.584 | J24: =+J9 -> 98524.757 | K24: =+K9 -> 38132.173 | ... R24: =+R9 -> 49709.866
C25: ACTIFS COURANTS | D25: =+D26+D27+D32 -> 78787.274 | E25: =+E26+E27+E32 -> 0 | F25: =+F26+F27+F32 -> 78787.274 | G25: =+G26+G27+G32 -> 78787.274 | H25: =+H26+H27+H32 -> 0 | I25: =+I26+I27+I32 -> 78787.274 | J25: =+J26+J27+J32 -> 78787.274 | K25: =+K26+K27+K32 -> 0 | ... R25: =+R26+R27+R32 -> 37290.267
C26: Stocks et encours | D26: 54424.256 | F26: =+D26-E26 -> 54424.256 | G26: 54424.256 | I26: =+G26-H26 -> 54424.256 | J26: 54424.256 | L26: =+J26-K26 -> 54424.256 | M26: 19958.44 | O26: =+M26-N26 -> 19958.44 | P26: 19958.44 | R26: =+P26-Q26 -> 19958.44
C27: Créances et emplois assimilés | D27: =+D28+D29+D30+D31 -> 24068.253 | E27: =+E28+E29+E30+E31 -> 0 | F27: =+F28+F29+F30+F31 -> 24068.253 | G27: =+G28+G29+G30+G31 -> 24068.253 | H27: =+H28+H29+H30+H31 -> 0 | I27: =+I28+I29+I30+I31 -> 24068.253 | J27: =+J28+J29+J30+J31 -> 24068.253 | K27: =+K28+K29+K30+K31 -> 0 | ... R27: =+R28+R29+R30+R31 -> 15195.673
C28: Clients | D28: 4802.292 | F28: =+D28-E28 -> 4802.292 | G28: 4802.292 | I28: =+G28-H28 -> 4802.292 | J28: 4802.292 | L28: =+J28-K28 -> 4802.292 | M28: 3495.623 | O28: =+M28-N28 -> 3495.623 | P28: 3495.623 | R28: =+P28-Q28 -> 3495.623
C29: Autres débiteurs | D29: 3943.005 | F29: =+D29-E29 -> 3943.005 | G29: 3943.005 | I29: =+G29-H29 -> 3943.005 | J29: 3943.005 | L29: =+J29-K29 -> 3943.005 | M29: 323.699 | O29: =+M29-N29 -> 323.699 | P29: 323.699 | R29: =+P29-Q29 -> 323.699
C30: Impôts et assimilés | D30: 15322.956 | F30: =+D30-E30 -> 15322.956 | G30: 15322.956 | I30: =+G30-H30 -> 15322.956 | J30: 15322.956 | L30: =+J30-K30 -> 15322.956 | M30: 11376.351 | O30: =+M30-N30 -> 11376.351 | P30: 11376.351 | R30: =+P30-Q30 -> 11376.351
C31: Autres créances et emplois assimilés | F31: =+D31-E31 -> 0 | I31: =+G31-H31 -> 0 | L31: =+J31-K31 -> 0 | O31: =+M31-N31 -> 0 | R31: =+P31-Q31 -> 0
C32: Disponibilités et assimilés | D32: =+D33+D34 -> 294.765 | E32: =+E33+E34 -> 0 | F32: =+F33+F34 -> 294.765 | G32: =+G33+G34 -> 294.765 | H32: =+H33+H34 -> 0 | I32: =+I33+I34 -> 294.765 | J32: =+J33+J34 -> 294.765 | K32: =+K33+K34 -> 0 | ... R32: =+R33+R34 -> 2136.154
C33: Placements et autres actifs financiers courants | F33: =+D33-E33 -> 0 | I33: =+G33-H33 -> 0 | L33: =+J33-K33 -> 0 | O33: =+M33-N33 -> 0 | R33: =+P33-Q33 -> 0
C34: Trésorerie | D34: 294.765 | F34: =+D34-E34 -> 294.765 | G34: 294.765 | I34: =+G34-H34 -> 294.765 | J34: 294.765 | L34: =+J34-K34 -> 294.765 | M34: 2136.154 | O34: =+M34-N34 -> 2136.154 | P34: 2136.154 | R34: =+P34-Q34 -> 2136.154
C35: TOTAL ACTIF COURANT | D35: =+D25 -> 78787.274 | E35: =+E25 -> 0 | F35: =+F25 -> 78787.274 | G35: =+G25 -> 78787.274 | H35: =+H25 -> 0 | I35: =+I25 -> 78787.274 | J35: =+J25 -> 78787.274 | K35: =+K25 -> 0 | ... R35: =+R25 -> 37290.267
C36: TOTAL GENERAL ACTIF | D36: =+D35+D24 -> 177312.03 | E36: =+E35+E24 -> 38132.173 | F36: =+F35+F24 -> 139179.86 | G36: =+G35+G24 -> 177312.03 | H36: =+H35+H24 -> 38132.173 | I36: =+I35+I24 -> 139179.86 | J36: =+J35+J24 -> 177312.03 | K36: =+K35+K24 -> 38132.173 | ... R36: =+R35+R24 -> 87000.133

Sheet Saisie passif
C1: Raison sociale
C2: NIF
C3: Source
C4: PASSIF | D4: N-4 | E4: N-3 | F4: N-2 | G4: N-1 | H4: N
C5: CAPITAUX PROPRES : | D5: =D6-D7+SUM(D8:D12) -> 77953.808 | E5: =E6-E7+SUM(E8:E12) -> 77953.808 | F5: =F6-F7+SUM(F8:F12) -> 0 | G5: =G6-G7+SUM(G8:G12) -> 77953.808 | H5: =H6-H7+SUM(H8:H12) -> 64767.33
C6: Capital émis | D6: 62541.411 | E6: 62541.411 | G6: 62541.411 | H6: 50465
C7: Capital non appelé
C8: Primes et réserves- Réserves consolidées(1)
C9: Ecarts de réévaluation
C10: Ecart d’équivalence (1)
C11: Résultat net - Résultat net part du groupe (1) | D11: 15412.397 | E11: 15412.397 | G11: 15412.397 | H11: 14302.33
C12: Autres capitaux propres – Report à nouveau
C13: Part de la société consolidante (1)
C14: Part des minoritaires (1)
C15: TOTAL I (KDZD) | D15: =+D5 -> 77953.808 | E15: =+E5 -> 77953.808 | F15: =+F5 -> 0 | G15: =+G5 -> 77953.808 | H15: =+H5 -> 64767.33
C16: PASSIFS NON-COURANTS : | D16: =SUM(D17:D20) -> 962.647 | E16: =SUM(E17:E20) -> 962.647 | F16: =SUM(F17:F20) -> 0 | G16: =SUM(G17:G20) -> 962.647 | H16: =SUM(H17:H20) -> 4689.417
C17: Emprunts et dettes financières
C18: Impôts (différés et provisionnés) | D18: 962.647 | E18: 962.647 | G18: 962.647 | H18: 4689.417
C19: Autres dettes non courantes
C20: Provisions et produits constatés d’avance
C21: TOTAL II (KDZD) | D21: =+D16 -> 962.647 | E21: =+E16 -> 962.647 | F21: =+F16 -> 0 | G21: =+G16 -> 962.647 | H21: =+H16 -> 4689.417
C22: PASSIFS COURANTS : | D22: =SUM(D23:D26) -> 60263.306 | E22: =SUM(E23:E26) -> 60263.306 | F22: =SUM(F23:F26) -> 0 | G22: =SUM(G23:G26) -> 60263.306 | H22: =SUM(H23:H26) -> 17543.426
C23: Fournisseurs et comptes rattachés | D23: 36959.869 | E23: 36959.869 | G23: 36959.869 | H23: 9867.194
C24: Impôts | D24: 4353.557 | E24: 4353.557 | G24: 4353.557 | H24: 2930.995
C25: Autres dettes | D25: =11597.945 -> 11597.945 | E25: =11597.945 -> 11597.945 | G25: =11597.945 -> 11597.945 | H25: =646.477+0.2 -> 646.677
C26: Trésorerie Passif | D26: 7351.935 | E26: 7351.935 | G26: 7351.935 | H26: 4098.56
C27: TOTAL III (KDZD) | D27: =+D22 -> 60263.306 | E27: =+E22 -> 60263.306 | F27: =+F22 -> 0 | G27: =+G22 -> 60263.306 | H27: =+H22 -> 17543.426
C28: TOTAL PASSIF (I+II+III) (KDZD) | D28: =+D27+D21+D15 -> 139179.76 | E28: =+E27+E21+E15 -> 139179.76 | F28: =+F27+F21+F15 -> 0 | G28: =+G27+G21+G15 -> 139179.76 | H28: =+H27+H21+H15 -> 87000.173
D29: =IF(OR(D28-'[1]Saisie actif'!F34<=-0.1,D28-'[1]Saisie actif'!F34>=0.1),"ERREUR (Actif ≠ Passif)","OK (Actif = Passif)") -> OK (Actif = Passif) | E29: =IF(OR(E28-'[1]Saisie actif'!P34<=-0.1,E28-'[1]Saisie actif'!P34>=0.1),"ERREUR (Actif ≠ Passif)","OK (Actif = Passif)") -> ERREUR (Actif ≠ Passif) | G29: =IF(OR(G28-'[1]Saisie actif'!R34<=-0.1,G28-'[1]Saisie actif'!R34>=0.1),"ERREUR (Actif ≠ Passif)","OK (Actif = Passif)") -> ERREUR (Actif ≠ Passif) | H29: =IF(OR(H28-'[1]Saisie actif'!U34<=-0.1,H28-'[1]Saisie actif'!U34>=0.1),"ERREUR (Actif ≠ Passif)","OK (Actif = Passif)") -> ERREUR (Actif ≠ Passif)
D30: =IF(D29="ERREUR (Actif ≠ Passif)",-D28+'[1]Saisie actif'!F34,"") | E30: =IF(E29="ERREUR (Actif ≠ Passif)",-E28+'[1]Saisie actif'!P34,"") -> -23101.464 | G30: =IF(G29="ERREUR (Actif ≠ Passif)",-G28+'[1]Saisie actif'!R34,"") -> -52179.628 | H30: =IF(H29="ERREUR (Actif ≠ Passif)",-H28+'[1]Saisie actif'!U34,"") -> -87000.173
C31: (1) à utiliser uniquement pour la présentation d’états financiers consolidés

Sheet Saisie TCR
C1: Raison sociale
C2: NIF
C3: Source
C4: Rubriques | E4: N-4 | G4: N-3 | I4: N-2 | K4: N-1 | M4: N
E5: DEBIT (en Dinars) | F5: CREDIT (en Dinars) | G5: DEBIT (en Dinars) | H5: CREDIT (en Dinars) | I5: DEBIT (en Dinars) | J5: CREDIT (en Dinars) | K5: DEBIT (KDZD) | L5: CREDIT (KDZD) | M5: DEBIT (KDZD) | N5: CREDIT (KDZD)
C6: Ventes de marchandises | L6: 246152.99 | N6: 223276.08
C7: Production vendue | D7: Produits fabriqués
D8: Prestations de services
D9: Vente de travaux
C10: Produits annexes
C11: Rabais, remises, ristournes accordés
C12: Chiffre d’affaires net des Rabais, remises, ristournes | E12: =(IF((SUM(E6:E11))>(SUM(F6:F11)),(+F6+F7+F8+F9+F10+F11-E6-E7-E8-E9-E10-E11),0))*(-1) -> 0 | F12: =IF((SUM(F6:F11))>(SUM(E6:E11)),(+F6+F7+F8+F9+F10+F11-E6-E7-E8-E9-E10-E11),0) -> 0 | G12: =(IF((SUM(G6:G11))>(SUM(H6:H11)),(+H6+H7+H8+H9+H10+H11-G6-G7-G8-G9-G10-G11),0))*(-1) -> 0 | H12: =IF((SUM(H6:H11))>(SUM(G6:G11)),(+H6+H7+H8+H9+H10+H11-G6-G7-G8-G9-G10-G11),0) -> 0 | I12: =(IF((SUM(I6:I11))>(SUM(J6:J11)),(+J6+J7+J8+J9+J10+J11-I6-I7-I8-I9-I10-I11),0))*(-1) -> 0 | J12: =IF((SUM(J6:J11))>(SUM(I6:I11)),(+J6+J7+J8+J9+J10+J11-I6-I7-I8-I9-I10-I11),0) -> 0 | K12: =(IF((SUM(K6:K11))>(SUM(L6:L11)),(+L6+L7+L8+L9+L10+L11-K6-K7-K8-K9-K10-K11),0))*(-1) -> 0 | L12: =IF((SUM(L6:L11))>(SUM(K6:K11)),(+L6+L7+L8+L9+L10+L11-K6-K7-K8-K9-K10-K11),0) -> 246152.99 | M12: =(IF((SUM(M6:M11))>(SUM(N6:N11)),(+N6+N7+N8+N9+N10+N11-M6-M7-M8-M9-M10-M11),0))*(-1) -> 0 | N12: =IF((SUM(N6:N11))>(SUM(M6:M11)),(+N6+N7+N8+N9+N10+N11-M6-M7-M8-M9-M10-M11),0) -> 223276.08
C13: Production stockée ou déstockée
C14: Production immobilisée
C15: Subventions d’exploitation
C16: I-Production de l’exercice | E16: =(IF((SUM(E12:E15))>(SUM(F12:F15)),(+F12+F13+F14+F15-E12-E13-E14-E15),0))*(-1) -> 0 | F16: =IF((SUM(F12:F15))>(SUM(E12:E15)),(+F12+F13+F14+F15-E12-E13-E14-E15),0) -> 0 | G16: =(IF((SUM(G12:G15))>(SUM(H12:H15)),(+H12+H13+H14+H15-G12-G13-G14-G15),0))*(-1) -> 0 | H16: =IF((SUM(H12:H15))>(SUM(G12:G15)),(+H12+H13+H14+H15-G12-G13-G14-G15),0) -> 0 | I16: =(IF((SUM(I12:I15))>(SUM(J12:J15)),(+J12+J13+J14+J15-I12-I13-I14-I15),0))*(-1) -> 0 | J16: =IF((SUM(J12:J15))>(SUM(I12:I15)),(+J12+J13+J14+J15-I12-I13-I14-I15),0) -> 0 | K16: =(IF((SUM(K12:K15))>(SUM(L12:L15)),(+L12+L13+L14+L15-K12-K13-K14-K15),0))*(-1) -> 0 | L16: =IF((SUM(L12:L15))>(SUM(K12:K15)),(+L12+L13+L14+L15-K12-K13-K14-K15),0) -> 246152.99 | M16: =(IF((SUM(M12:M15))>(SUM(N12:N15)),(+N12+N13+N14+N15-M12-M13-M14-M15),0))*(-1) -> 0 | N16: =IF((SUM(N12:N15))>(SUM(M12:M15)),(+N12+N13+N14+N15-M12-M13-M14-M15),0) -> 223276.08
C17: Achats de marchandises vendues
C18: Matières premières | K18: 165273.99 | M18: 150424.33
C19: Autres approvisionnements
C20: Variations des stocks
C21: Achats d’études et de prestations de services
C22: Autres consommations | M22: 2683.194
C23: Rabais, remises, ristournes obtenus sur achats
C24: Services extérieurs | D24: Sous-traitance générale | M24: 3155.879
D25: Locations | M25: 1002
D26: Entretien, réparations et maintenance | M26: 396.062
D27: Primes d'assurances | M27: 271.079
D28: Personnel extérieur à l’entreprise
D29: Rémunération d’intermédiaires et honoraires | M29: 2548.207
D30: Publicité | M30: 103.47
D31: Déplacements, missions et réceptions
C32: Autres services | K32: 18155.68 | M32: 6958.35
C33: Rabais, remises, ristournes obtenus sur services extérieurs
C34: II-Consommations de l’exercice | E34: =(IF((SUM(E17:E33))>(SUM(F17:F33)),(+(SUM(F17:F33))-(SUM(E17:E33))),0))*(-1) -> 0 | F34: =IF((SUM(F17:F33))>(SUM(E17:E33)),(+(SUM(F17:F33))-(SUM(E17:E33))),0) -> 0 | G34: =(IF((SUM(G17:G33))>(SUM(H17:H33)),(+(SUM(H17:H33))-(SUM(G17:G33))),0))*(-1) -> 0 | H34: =IF((SUM(H17:H33))>(SUM(G17:G33)),(+(SUM(H17:H33))-(SUM(G17:G33))),0) -> 0 | I34: =(IF((SUM(I17:I33))>(SUM(J17:J33)),(+(SUM(J17:J33))-(SUM(I17:I33))),0))*(-1) -> 0 | J34: =IF((SUM(J17:J33))>(SUM(I17:I33)),(+(SUM(J17:J33))-(SUM(I17:I33))),0) -> 0 | K34: =(IF((SUM(K17:K33))>(SUM(L17:L33)),(+(SUM(L17:L33))-(SUM(K17:K33))),0))*(-1) -> 183429.67 | L34: =IF((SUM(L17:L33))>(SUM(K17:K33)),(+(SUM(L17:L33))-(SUM(K17:K33))),0) -> 0 | M34: =(IF((SUM(M17:M33))>(SUM(N17:N33)),(+(SUM(N17:N33))-(SUM(M17:M33))),0))*(-1) -> 167542.57 | N34: =IF((SUM(N17:N33))>(SUM(M17:M33)),(+(SUM(N17:N33))-(SUM(M17:M33))),0) -> 0
C35: III-Valeur ajoutée d’exploitation (I–II) | E35: =(IF(((+E34+E16)>(+F34+F16)),(+F34+F16-E34-E16),0))*(-1) -> 0 | F35: =+IF(((+F34+F16)>(+E34+E16)),(-E34-E16+F34+F16),0) -> 0 | G35: =(IF(((+G34+G16)>(+H34+H16)),(+H34+H16-G34-G16),0))*(-1) -> 0 | H35: =+IF(((+H34+H16)>(+G34+G16)),(-G34-G16+H34+H16),0) -> 0 | I35: =(IF(((+I34+I16)>(+J34+J16)),(+J34+J16-I34-I16),0))*(-1) -> 0 | J35: =+IF(((+J34+J16)>(+I34+I16)),(-I34-I16+J34+J16),0) -> 0 | K35: =(IF(((+K34+K16)>(+L34+L16)),(+L34+L16-K34-K16),0))*(-1) -> 0 | L35: =+IF(((+L34+L16)>(+K34+K16)),(-K34-K16+L34+L16),0) -> 62723.317 | M35: =(IF(((+M34+M16)>(+N34+N16)),(+N34+N16-M34-M16),0))*(-1) -> 0 | N35: =+IF(((+N34+N16)>(+M34+M16)),(-M34-M16+N34+N16),0) -> 55733.518
D36: Charges de personnel | K36: 29033.924 | M36: 21966.003
D37: Impôts et taxes et versements assimilés | K37: 4958.721 | M37: 4518.579
C38: IV-Excédent brut d’exploitation | E38: =(IF((SUM(E35:E37))>(SUM(F35:F37)),(+(SUM(F35:F37))-(SUM(E35:E37))),0))*(-1) -> 0 | F38: =IF((SUM(F35:F37))>(SUM(E35:E37)),(+(SUM(F35:F37))-(SUM(E35:E37))),0) -> 0 | G38: =(IF((SUM(G35:G37))>(SUM(H35:H37)),(+(SUM(H35:H37))-(SUM(G35:G37))),0))*(-1) -> 0 | H38: =IF((SUM(H35:H37))>(SUM(G35:G37)),(+(SUM(H35:H37))-(SUM(G35:G37))),0) -> 0 | I38: =(IF((SUM(I35:I37))>(SUM(J35:J37)),(+(SUM(J35:J37))-(SUM(I35:I37))),0))*(-1) -> 0 | J38: =IF((SUM(J35:J37))>(SUM(I35:I37)),(+(SUM(J35:J37))-(SUM(I35:I37))),0) -> 0 | K38: =(IF((SUM(K35:K37))>(SUM(L35:L37)),(+(SUM(L35:L37))-(SUM(K35:K37))),0))*(-1) -> 0 | L38: =IF((SUM(L35:L37))>(SUM(K35:K37)),(+(SUM(L35:L37))-(SUM(K35:K37))),0) -> 28730.672 | M38: =(IF((SUM(M35:M37))>(SUM(N35:N37)),(+(SUM(N35:N37))-(SUM(M35:M37))),0))*(-1) -> 0 | N38: =IF((SUM(N35:N37))>(SUM(M35:M37)),(+(SUM(N35:N37))-(SUM(M35:M37))),0) -> 29248.936
C39: Autres produits opérationnels | N39: 108.803
C40: Autres charges opérationnelles | K40: 5 | M40: 3875.82
...

Sheet Saisie
C1: Unité de compte (M.EUR, M.USD, ...) : | D1: 000' DZD | I1: =TODAY() -> 46304 | N1: =TODAY() -> 46304
B2: Société: | C2: MERIPLAST | E2: Feuille de Saisie
A3: Référence Liasse Fiscale | B3: Groupe: | C3: SARL | D3: 38322 | E3: 39417 | F3: 39783 | G3: 40178 | H3: 40543 | I3: 46022 | N3: =IF('Saisie actif'!U7="","",'Saisie actif'!U7)
B4: Immo. d'exploitation brutes (incorporelles) | D4: =D5+D6+D7+D8-D9 -> 0 | E4: =E5+E6+E7+E8-E9 -> 0 | F4: =F5+F6+F7+F8-F9 -> 41.25 | G4: =G5+G6+G7+G8-G9 -> 16 | H4: =H5+H6+H7+H8-H9 -> 565.545 | I4: =I5+I6+I7+I8-I9 -> 1520 | N4: =N5+N6+N7+N8-N9 -> 0
A5: AB | C5: Frais d'établissement bruts | F5: 41.25
A6: CM | C6: + Prime de remb. sur emprunt oblig.
C7: (+ charges à répartir sur plusieurs exercices, uniquement pour la part relative aux immo. industrielles)
A8: AD+AF+AH+AJ+AL | C8: + Autres immo. incorporelles brutes | G8: 16 | H8: 565.545 | I8: =+'Saisie actif'!P11 -> 1520 | N8: =+'Saisie actif'!U11 -> 0
C9: - Survaleur / goodwill bruts (si inclus)
B10: Amortissemts (& prov.) immo. incorporelles | D10: =D11-D12 -> 0 | E10: =E11-E12 -> 0 | F10: =F11-F12 -> 0 | G10: =G11-G12 -> 1.466 | H10: =H11-H12 -> 146.378 | I10: =I11-I12 -> 459 | N10: =N11-N12 -> 0
A11: AC+AE+AG+AI+AK+AM | C11: Amts sur immo. incorporelles. | G11: 1.466 | H11: 146.378 | I11: =+'Saisie actif'!Q11 -> 459 | N11: =+'Saisie actif'!V11 -> 0
C12: - Amts de la survaleur (si inclus)
B13: Immo. d'exploitation brutes (corporelles) | D13: =D14 -> 0 | E13: =E14 -> 88086.06 | F13: =F14 -> 149479.02 | G13: =G14 -> 161659.93 | H13: =H14 -> 186870.25 | I13: =I14 -> 77268.03 | N13: =N14 -> 0
A14: AN+AP+AR+AT+AV+AX | C14: Immo. corporelles brutes | E14: =9696+272.509+62035.547+4500+11543.704+38.3 -> 88086.06 | F14: =9696+139709.67525+73.34273 -> 149479.02 | G14: =9696+272.509+125326.285+4500+21791.794+73.342 -> 161659.93 | H14: 186870.25 | I14: =+'Saisie actif'!P12+'Saisie actif'!P17 -> 77268.03 | N14: =+'Saisie actif'!U12+'Saisie actif'!U17 -> 0
B15: Amortissemts (& prov.) immo. corporelles | D15: =+D16 -> 0 | E15: =+E16 -> 23976.664 | F15: =+F16 -> 43340.142 | G15: =+G16 -> 64226.37 | H15: =+H16 -> 91639.346 | I15: =+I16 -> 28619.164 | N15: =+N16 -> 0
A16: AO+AQ+AS+AU+AW+AY | C16: Amts sur immo. corporelles. | E16: =271.374+14103.339+4440+5142.255+19.696 -> 23976.664 | F16: =43312.07271+28.06925 -> 43340.142 | G16: =272.509+50210.372+4500+9204.419+39.07 -> 64226.37 | H16: 91639.346 | I16: =+'Saisie actif'!Q12+'Saisie actif'!Q17 -> 28619.164 | J16: ='Saisie actif'!$E$14 -> 925 | N16: =+'Saisie actif'!V12+'Saisie actif'!V17 -> 0
B17: Survaleur/ goodwill/ écart d'acquisit. nets | D17: =D18-D19 -> 0 | E17: =E18-E19 -> 0 | F17: =F18-F19 -> 0 | G17: =G18-G19 -> 0 | H17: 0 | I17: =I18-I19 -> 0 | N17: =N18-N19 -> 0
C18: Survaleur / goodwill brut(s) | I18: =+'Saisie actif'!P10 -> 0 | N18: =+'Saisie actif'!U10 -> 0
C19: - Amt de la survaleur / goodwill | I19: =+'Saisie actif'!Q10 -> 0 | N19: =+'Saisie actif'!V10 -> 0
B20: Immo. financières nettes | D20: =D21+D22+D23+D24+D25+D26-D27-D28-D29-D30-D31-D32 -> 0 | E20: =E21+E22+E23+E24+E25+E26-E27-E28-E29-E30-E31-E32 -> 51512.928 | F20: =F21+F22+F23+F24+F25+F26-F27-F28-F29-F30-F31-F32 -> 51512.928 | G20: =G21+G22+G23+G24+G25+G26-G27-G28-G29-G30-G31-G32 -> 3813.992 | H20: =H21+H22+H23+H24+H25+H26-H27-H28-H29-H30-H31-H32 -> 1847 | I20: =I21+I22+I23+I24+I25+I26-I27-I28-I29-I30-I31-I32 -> 0 | N20: =N21-N22 -> 0
A21: CS+CU | B21: Brut : | C21: Participations
C22: + Titres des stés mises en équival. | I22: =+'Saisie actif'!P19 -> 0 | N22: =+'Saisie actif'!U19 -> 0
C23: + VMP nanties ou bloquées
A24: BD | C24: + Autres titres immobilisés | I24: =+'Saisie actif'!P21 -> 0 | N24: =+'Saisie actif'!U21 -> 0
A25: BF | C25: + Prêts | H25: 1847 | I25: =+'Saisie actif'!P22 -> 0 | N25: =+'Saisie actif'!U22 -> 0
A26: BH | C26: + Autres immo. financières | E26: 51512.928 | F26: 51512.928 | G26: =3813.992 -> 3813.992 | I26: =+'Saisie actif'!P20+'Saisie actif'!P23 -> 0 | N26: =+'Saisie actif'!U20+'Saisie actif'!U23 -> 0
A27: CT+CV | B27: - Prov.: | C27: pour participations
C28: pour titres stés mises en équival. | I28: =+'Saisie actif'!Q19 -> 0 | N28: =+'Saisie actif'!V19 -> 0
C29: pour VMP nanties ou bloquées
A30: BE | C30: pour autres titres immobilisés | I30: =+'Saisie actif'!Q21 -> 0 | N30: =+'Saisie actif'!V21 -> 0
A31: BG | C31: pour prêts | I31: =+'Saisie actif'!Q22 -> 0 | N31: =+'Saisie actif'!V22 -> 0
A32: BI | C32: pour autres immo. financières | I32: =+'Saisie actif'!Q20+'Saisie actif'!Q23 -> 0 | N32: =+'Saisie actif'!V20+'Saisie actif'!V23 -> 0
B33: Sociétés apparentées (actif) nettes | D33: =D34+D35-D36 -> 0 | E33: =E34+E35-E36 -> 0 | F33: =F34+F35-F36 -> 0 | G33: =G34+G35-G36 -> 421.393 | H33: 0 | I33: =I34+I35-I36 -> 0 | N33: =N34+N35-N36 -> 0
A34: BB | B34: Brut : | C34: Créances rattach. à des partic.
A35: VC Annexe 8 | C35: + Créances Groupe & associés | G35: 421.393 | J35: ce poste est généralement compris dans les autres créances de l'actif circulant: on en trouve le détail dans les annexes des états financiers (sinon info à demander aux entreprises)
A36: BC | B36: - Prov.: | C36: - Provis. pour créances rattachées à des participations
B37: Stocks nets | D37: =D38+D39+D40+D41-D42-D43-D44-D45 -> 0 | E37: =E38+E39+E40+E41-E42-E43-E44-E45 -> 108697.29 | F37: =F38+F39+F40+F41-F42-F43-F44-F45 -> 262709.32 | G37: =G38+G39+G40+G41-G42-G43-G44-G45 -> 475743.81 | H37: =H38+H39+H40+H41-H42-H43-H44-H45 -> 444621.94 | I37: =I38+I39+I40+I41-I42-I43-I44-I45 -> 19958.44 | N37: =N38+N39+N40+N41-N42-N43-N44-N45 -> 0
A38: BL | B38: Brut : | C38: Matières premières & approv. | E38: 108697.29 | F38: 256279 | G38: 475743.81
A39: BT | C39: + Marchandises | F39: =3416.52753+3013.79138 -> 6430.3189 | H39: 444621.94 | I39: =+'Saisie actif'!P26 -> 19958.44 | N39: =+'Saisie actif'!U26 -> 0
A40: BN+BP | C40: + Encours prod. biens & services
...

Sheet Etatsfin
A1: Unité de compte (MF, MUSD, ...): | D1: =IF(Saisie!D1="","Saisir sur Saisie ou Etatsfin",Saisie!D1) -> 000' DZD | F1: ETATS FINANCIERS | K1: Date : | L1: =TODAY() -> 46304 | O1: =IF(OR(D1="",D1="Saisir sur Saisie ou Etatsfin")," montant",D1) -> 000' DZD | P1: =IF(OR(D1="",D1="Saisir sur Saisie ou Etatsfin")," Saisir sur Saisie ou Etatsfin",D1) -> 000' DZD
A2: Société : | D2: =IF(Saisie!C2="","Saisir sur Saisie ou Etatsfin",Saisie!C2) -> MERIPLAST | I2: Commissaires aux comptes : | L2: Consolidé :
A3: Groupe : | D3: =IF(Saisie!C3="","Saisir sur Saisie ou Etatsfin",Saisie!C3) -> SARL | L3: Audité :
A4: Saisie automatisée (même partiellement) ? (o/n): | G4: si oui, les contrôles spécifiques sont-ils effectués ? (o/n): | H4: si oui, les contrôles spécifiques sont-ils effectués ? (o/n): | O4: =(Saisie!E3-Saisie!D3) -> 1095 | P4: (Détermination de la durée du 1er exercice)
A5: ACTIF | C5: =IF(Saisie!D3=0,D5-365,Saisie!D3) -> 38322 | D5: =IF(Saisie!E3=0,E5-365,Saisie!E3) -> 39417 | E5: =IF(Saisie!F3=0,F5-365,Saisie!F3) -> 39783 | F5: =IF(Saisie!G3=0,G5-365,Saisie!G3) -> 40178 | G5: =IF(Saisie!H3=0,0,Saisie!H3) -> 40543 | H5: =IF(Saisie!I3=0,0,Saisie!I3) -> 46022 | I5: PASSIF | J5: =D5 -> 39417 | K5: =E5 -> 39783 | L5: =F5 -> 40178 | M5: =G5 -> 40543 | N5: =H5 -> 46022
C6: =O4/365 -> 3 | D6: =O4/365 -> 3 | E6: =(E5-D5)/365 -> 1.0027397 | F6: =(F5-E5)/365 -> 1.0821918 | G6: =(G5-F5)/365 -> 1 | H6: =(H5-G5)/365 -> 15.010959
A7: =IF(OR(G5=0,G5=""),"Date d'arrêté à saisir ci-dessous en ''G'', ligne 23, dans la cellule blanche.","") | D7: Fiscal | E7: Fiscal | F7: Fiscal | G7: fiscal | H7: fiscal | I7: =IF(OR(O4<=0,O4=""),"Saisir durée, en jours, du 1er exercice histo., dans la cellule ''M'' ici à droite, ligne 22 :","") | J7: =J8/J31 -> 0.22643745 | K7: =K8/K31 -> 0.16324502 | L7: =L8/L31 -> 0.16304815 | M7: =M8/M31 -> 0.14166142 | N7: =N8/N31 -> 0.81499833
A8: Actifs immobilisés ( nets) | C8: =C14+C17+C18+C19 -> 0 | D8: =D14+D17+D18+D19 -> 115622.32 | E8: =E14+E17+E18+E19 -> 157693.05 | F8: =F14+F17+F18+F19 -> 101683.48 | G8: =G14+G17+G18+G19 -> 97497.075 | H8: =H14+H17+H18+H19 -> 49709.866 | I8: Fonds propres | J8: =J10+J11+J12+J13 -> 85587.931 | K8: =K10+K11+K12+K13 -> 105471.02 | L8: =L10+L11+L12+L13 -> 126814.25 | M8: =M10+M11+M12+M13 -> 157044.05 | N8: =N10+N11+N12+N13 -> 97943.605
A10: Immobilisations d'exploitation brutes | C10: =Saisie!D4+Saisie!D13 -> 0 | D10: =Saisie!E4+Saisie!E13 -> 88086.06 | E10: =Saisie!F4+Saisie!F13 -> 149520.27 | F10: =Saisie!G4+Saisie!G13 -> 161675.93 | G10: =Saisie!H4+Saisie!H13 -> 187435.8 | H10: =Saisie!I4+Saisie!I13 -> 78788.03 | I10: Capital | J10: =Saisie!E67 -> 55000 | K10: =Saisie!F67 -> 55000 | L10: =Saisie!G67 -> 55000 | M10: =Saisie!H67 -> 55000 | N10: =Saisie!I67 -> 50465
A11: - Amortissements et Provisions | C11: =Saisie!D10+Saisie!D15 -> 0 | D11: =Saisie!E10+Saisie!E15 -> 23976.664 | E11: =Saisie!F10+Saisie!F15 -> 43340.142 | F11: =Saisie!G10+Saisie!G15 -> 64227.836 | G11: =Saisie!H10+Saisie!H15 -> 91785.724 | H11: =Saisie!I10+Saisie!I15 -> 29078.164 | I11: Réserves | J11: =Saisie!E71 -> 21587.473 | K11: =Saisie!F71 -> 32088.007 | L11: =Saisie!G71 -> 50446.013 | M11: =Saisie!H71 -> 74277.392 | N11: =Saisie!I71 -> 33176.275
I12: Bénéfice | J12: =Saisie!E77 -> 9000.4575 | K12: =Saisie!F77 -> 18383.009 | L12: =Saisie!G77 -> 21368.238 | M12: =Saisie!H77 -> 27766.661 | N12: =Saisie!I77 -> 14302.33
I13: Intérêts minoritaires | J13: =Saisie!E80 -> 0 | K13: =Saisie!F80 -> 0 | L13: =Saisie!G80 -> 0 | M13: =Saisie!H80 -> 0 | N13: =Saisie!I80 -> 0
A14: = Immobilisations nettes | C14: =C10-C11 -> 0 | D14: =D10-D11 -> 64109.396 | E14: =E10-E11 -> 106180.13 | F14: =F10-F11 -> 97448.094 | G14: =G10-G11 -> 95650.075 | H14: =H10-H11 -> 49709.866
A15: <dt immo. incorporelles nettes> | C15: =Saisie!D4-Saisie!D10 -> 0 | D15: =Saisie!E4-Saisie!E10 -> 0 | E15: =Saisie!F4-Saisie!F10 -> 41.25 | F15: =Saisie!G4-Saisie!G10 -> 14.534 | G15: =Saisie!H4-Saisie!H10 -> 419.167 | H15: =Saisie!I4-Saisie!I10 -> 1061 | I15: Prov. risques et charges stables | J15: =Saisie!E83 -> 0 | K15: =Saisie!F83 -> 0 | L15: =Saisie!G83 -> 0 | M15: =Saisie!H83 -> 0 | N15: =Saisie!I83 -> 0
A17: Survaleur/ Goodwill | C17: =Saisie!D17 -> 0 | D17: =Saisie!E17 -> 0 | E17: =Saisie!F17 -> 0 | F17: =Saisie!G17 -> 0 | G17: =Saisie!H17 -> 0 | H17: =Saisie!I17 -> 0 | I17: Dettes à long / moyen terme | J17: =J19+J21 -> 98967.399 | K17: =K19+K21 -> 129227.14 | L17: =L19+L21 -> 122730.39 | M17: =M19+M21 -> 123773.39 | N17: =N19+N21 -> 0
A18: Immobilisations financières nettes | C18: =Saisie!D20 -> 0 | D18: =Saisie!E20 -> 51512.928 | E18: =Saisie!F20 -> 51512.928 | F18: =Saisie!G20 -> 3813.992 | G18: =Saisie!H20 -> 1847 | H18: =Saisie!I20 -> 0
A19: Sociétés apparentées | C19: =Saisie!D33 -> 0 | D19: =Saisie!E33 -> 0 | E19: =Saisie!F33 -> 0 | F19: =Saisie!G33 -> 421.393 | G19: =Saisie!H33 -> 0 | H19: =Saisie!I33 -> 0 | I19: Dettes financières | J19: =Saisie!E86 -> 45584 | K19: =Saisie!F86 -> 50953.402 | L19: =Saisie!G86 -> 50000 | M19: =Saisie!H86 -> 51043.006 | N19: =Saisie!I86 -> 0
I20: <y compris annuités moins d'1 an> | J20: =Saisie!E192 -> 0 | K20: =Saisie!F192 -> 0 | L20: =Saisie!G192 -> 0 | M20: =Saisie!H192 -> 0 | N20: =Saisie!I192 -> 0
A21: Actifs circulants (nets) | C21: =C23+C25+C26+C27+C28 -> 0 | D21: =D23+D25+D26+D27+D28 -> 262353.72 | E21: =E23+E25+E26+E27+E28 -> 488397.22 | F21: =F23+F25+F26+F27+F28 -> 676088.32 | G21: =G23+G25+G26+G27+G28 -> 1011090.3 | H21: =H23+H25+H26+H27+H28 -> 35357.561 | I21: Sociétés apparentées | J21: =Saisie!E96 -> 53383.399 | K21: =Saisie!F96 -> 78273.741 | L21: =Saisie!G96 -> 72730.389 | M21: =Saisie!H96 -> 72730.389 | N21: =Saisie!I96 -> 0
A23: Stocks | C23: =Saisie!D37 -> 0 | D23: =Saisie!E37 -> 108697.29 | E23: =Saisie!F37 -> 262709.32 | F23: =Saisie!G37 -> 475743.81 | G23: =Saisie!H37 -> 444621.94 | H23: =Saisie!I37 -> 19958.44 | I23: Exigibles court terme | J23: =J25+J26+J27+J29 -> 193420.71 | K23: =K25+K26+K27+K29 -> 411392.11 | L23: =L25+L26+L27+L29 -> 528227.16 | M23: =M25+M26+M27+M29 -> 827769.89 | N23: =N25+N26+N27+N29 -> 22232.843
A24: <dont travaux en cours> | C24: =Saisie!D40-Saisie!D44 -> 0 | D24: =Saisie!E40-Saisie!E44 -> 0 | E24: =Saisie!F40-Saisie!F44 -> 0 | F24: =Saisie!G40-Saisie!G44 -> 0 | G24: =Saisie!H40-Saisie!H44 -> 0 | H24: =Saisie!I40-Saisie!I44 -> 0
A25: Clients | C25: =Saisie!D46 -> 0 | D25: =Saisie!E46 -> 107718.96 | E25: =Saisie!F46 -> 57395.55 | F25: =Saisie!G46 -> 117587.54 | G25: =Saisie!H46 -> 383709.16 | H25: =Saisie!I46 -> 1296.442 | I25: Avances et Acomptes reçus | J25: =Saisie!E98 -> 0 | K25: =Saisie!F98 -> 296.0115 | L25: =Saisie!G98 -> 0 | M25: =Saisie!H98 -> 0 | N25: =Saisie!I98 -> 0
A26: Autres créances | C26: =Saisie!D49 -> 0 | D26: =Saisie!E49 -> 15533.525 | E26: =Saisie!F49 -> 41872.384 | F26: =Saisie!G49 -> 60028.927 | G26: =Saisie!H49 -> 78139.476 | H26: =Saisie!I49 -> 11966.525 | I26: Fournisseurs | J26: =Saisie!E100 -> 68995.586 | K26: =Saisie!F100 -> 205984.72 | L26: =Saisie!G100 -> 130093.2 | M26: =Saisie!H100 -> 331432.5 | N26: =Saisie!I100 -> 9867.194
A27: Valeurs mobilières de placement | C27: =Saisie!D58 -> 0 | D27: =Saisie!E58 -> 0 | E27: =Saisie!F58 -> 0 | F27: =Saisie!G58 -> 0 | G27: =Saisie!H58 -> 0 | H27: =Saisie!I58 -> 0 | I27: Autres dettes | J27: =Saisie!E102 -> 87623.951 | K27: =Saisie!F102 -> 16214.819 | L27: =Saisie!G102 -> 230249.91 | M27: =Saisie!H102 -> 44421.925 | N27: =Saisie!I102 -> 8267.089
A28: Disponible | C28: =Saisie!D62 -> 0 | D28: =Saisie!E62 -> 30403.941 | E28: =Saisie!F62 -> 126419.96 | F28: =Saisie!G62 -> 22728.054 | G28: =Saisie!H62 -> 104619.7 | H28: =Saisie!I62 -> 2136.154 | I28: <dont provisions et dividendes> | J28: =Saisie!E105+Saisie!E106+Saisie!E110+Saisie!E111 -> 0 | K28: =Saisie!F105+Saisie!F106+Saisie!F110+Saisie!F111 -> 0 | L28: =Saisie!G105+Saisie!G106+Saisie!G110+Saisie!G111 -> 0 | M28: =Saisie!H105+Saisie!H106+Saisie!H110+Saisie!H111 -> 844.248 | N28: =Saisie!I105+Saisie!I106+Saisie!I110+Saisie!I111 -> 4689.417
I29: Concours bancaires de trésorerie | J29: =Saisie!E112 -> 36801.173 | K29: =Saisie!F112 -> 188896.56 | L29: =Saisie!G112 -> 167884.05 | M29: =Saisie!H112 -> 451915.46 | N29: =Saisie!I112 -> 4098.56
A31: (*) Total Actif | C31: =C21+C8 -> 0 | D31: =D21+D8 -> 377976.04 | E31: =E21+E8 -> 646090.27 | F31: =F21+F8 -> 777771.8 | G31: =G21+G8 -> 1108587.3 | H31: =H21+H8 -> 85067.427 | I31: (*) Total Passif | J31: =J23+J17+J15+J8 -> 377976.04 | K31: =K23+K17+K15+K8 -> 646090.27 | L31: =L23+L17+L15+L8 -> 777771.8 | M31: =M23+M17+M15+M8 -> 1108587.3 | N31: =N23+N17+N15+N8 -> 120176.45
A32: =IF(AND(D32="",E32="",F32="",G32=""),""," Actif = Passif ?") | D32: =IF(AND(D31=0,J31=0),"",IF(AND((D31-J31)>=-0.1,(D31-J31)<=0.1),"","Erreur!")) | E32: =IF(AND(E31=0,K31=0),"",IF(AND((E31-K31)>=-0.1,(E31-K31)<=0.1),"","Erreur!")) | F32: =IF(AND(F31=0,L31=0),"",IF(AND((F31-L31)>=-0.1,(F31-L31)<=0.1),"","Erreur!")) | G32: =IF(AND(G31=0,M31=0),"",IF(AND((G31-M31)>=-0.1,(G31-M31)<=0.1),"","Erreur!")) | H32: =IF(AND(H31=0,N31=0),"",IF(AND((H31-N31)>=-0.1,(H31-N31)<=0.1),"","Erreur!")) -> Erreur! | I32: =IF(AND(D32="",E32="",F32="",G32=""),""," Si erreur, Actif - Passif = ?") | J32: =IF(D32="Erreur!",D31-J31,"") | K32: =IF(E32="Erreur!",E31-K31,"") | L32: =IF(F32="Erreur!",F31-L31,"") | M32: =IF(G32="Erreur!",G31-M31,"") | N32: =IF(H32="Erreur!",H31-N31,"") -> -35109.021
A33: Hors bilan | I33: Hors bilan
A34: Engagements reçus | D34: =Saisie!E65 -> 0 | E34: =Saisie!F65 -> 0 | F34: =Saisie!G65 -> 0 | G34: =Saisie!H65 -> 0 | H34: =Saisie!I65 -> 0 | I34: Effets escomptés non échus | J34: =Saisie!E115 -> 0 | K34: =Saisie!F115 -> 0 | L34: =Saisie!G115 -> 0 | M34: =Saisie!H115 -> 0 | N34: =Saisie!I115 -> 0
A35: Fonds de roulement | D35: =J8+J15+J17-J20-D8 -> 68933.005 | E35: =K8+K15+K17-K20-E8 -> 77005.105 | F35: =L8+L15+L17-L20-F8 -> 147861.16 | G35: =M8+M15+M17-M20-G8 -> 183320.37 | H35: =N8+N15+N17-N20-H8 -> 48233.739 | I35: Engagements de crédit bail | J35: =Saisie!E116 -> 0 | K35: =Saisie!F116 -> 0 | L35: =Saisie!G116 -> 16633.221 | M35: =Saisie!H116 -> 12000 | N35: =Saisie!I116 -> 12000
A36: Besoin en fonds de roulement (net) | D36: =-1*(J25+J26+J27-J28-D23-D25-D26+Saisie!E56) -> 75330.238 | E36: =-1*(K25+K26+K27-K28-E23-E25-E26+Saisie!F56) -> 139481.71 | F36: =-1*(L25+L26+L27-L28-F23-F25-F26+Saisie!G56) -> 293017.16 | G36: =-1*(M25+M26+M27-M28-G23-G25-G26+Saisie!H56) -> 531193.91 | H36: =-1*(N25+N26+N27-N28-H23-H25-H26+Saisie!I56) -> 19510.066 | I36: Autres | J36: =Saisie!E117 -> 0 | K36: =Saisie!F117 -> 0 | L36: =Saisie!G117 -> 0 | M36: =Saisie!H117 -> 0 | N36: =Saisie!I117 -> 0
A37: BFR (en Jours de C.A.) | D37: =IF(D41=0,"n/d ",(D36/D41)*360*D6) -> 195.46227 | E37: =IF(E41=0,"n/d ",(E36/E41)*360*E6) -> 70.129975 | F37: =IF(F41=0,"n/d ",(F36/F41)*360*F6) -> 125.75105 | G37: =IF(G41=0,"n/d ",(G36/G41)*360*G6) -> 118.32029 | H37: =IF(H41=0,"n/d ",(H36/H41)*360*H6) -> 472.20161
A38: Trésorerie | D38: =D35-D36 -> -6397.232 | E38: =E35-E36 -> -62476.6 | F38: =F35-F36 -> -145156 | G38: =G35-G36 -> -347873.54 | H38: =H35-H36 -> 28723.673
A39: COMPTE DE RESULTAT | D39: =D5 -> 39417 | E39: =E5 -> 39783 | F39: =F5 -> 40178 | G39: =G5 -> 40543 | H39: =H5 -> 46022 | I39: TABLEAU DE FLUX | J39: =D5 -> 39417 | K39: =E5 -> 39783 | L39: =F5 -> 40178 | M39: =G5 -> 40543 | N39: =H5 -> 46022
A41: Chiffre d'affaires H.T. | C41: =Saisie!D120 -> 0 | D41: =Saisie!E120 -> 416226.91 | E41: =Saisie!F120 -> 717966.67 | F41: =Saisie!G120 -> 907795.82 | G41: =Saisie!H120 -> 1616204.7 | H41: =Saisie!I120 -> 223276.08 | I41: Excédent Brut d'Exploitation | J41: =D56 -> 29838.884 | K41: =E56 -> 45113.275 | L41: =F56 -> 85384.745 | M41: =G56 -> 114043.95 | N41: =H56 -> 25481.919
A43: + Product° stockée et immobilisée | D43: =Saisie!E122+Saisie!E123 -> 0 | E43: =Saisie!F122+Saisie!F123 -> 0 | F43: =Saisie!G122+Saisie!G123 -> 17182.754 | G43: =Saisie!H122+Saisie!H123 -> 231.15 | H43: =Saisie!I122+Saisie!I123 -> 0 | I43: - Résultat financier retraité | J43: =D63-D65+(1/3*D64) -> 5350.758 | K43: =E63-E65+(1/3*E64) -> 7135.5244 | L43: =F63-F65+(1/3*F64) -> 23322.944 | M43: =G63-G65+(1/3*G64) -> 53131.535 | N43: =H63-H65+(1/3*H64) -> -1826.24
A44: + Autres produits | D44: =Saisie!E124 -> 0 | E44: =Saisie!F124 -> 0 | F44: =Saisie!G124 -> 2281.665 | G44: =Saisie!H124 -> 621.118 | H44: =Saisie!I124 -> 108.803 | I44: - Impôt sur les sociétés | J44: =D71 -> 3000.1525 | K44: =E71 -> 6127.6695 | L44: =F71 -> 6938.5937 | M44: =G71 -> 6990.363 | N44: =H71 -> 3580.982
A46: = Production | D46: =D41+D43+D44 -> 416226.91 | E46: =E41+E43+E44 -> 717966.67 | F46: =F41+F43+F44 -> 927260.24 | G46: =G41+G43+G44 -> 1617056.9 | H46: =H41+H43+H44 -> 223384.89 | I46: = Cashflow d'Exploitat° Brut | J46: =J41-J43-J44 -> 21487.973 | K46: =K41-K43-K44 -> 31850.081 | L46: =L41-L43-L44 -> 55123.207 | M46: =M41-M43-M44 -> 53922.055 | N46: =N41-N43-N44 -> 23727.177
A48: - Achats et sous-traitance | D48: =Saisie!E126 -> 365232.29 | E48: =Saisie!F126 -> 639351.23 | F48: =Saisie!G126 -> 765768.86 | G48: =Saisie!H126 -> 1379090.5 | H48: =Saisie!I126 -> 153580.2 | I48: Variation du BFR (brut) | J48: =J49+J50-J51+J52 -> 77529.42 | K48: =K49+K50-K51+K52 -> 64151.468 | L48: =L49+L50-L51+L52 -> 153535.45 | M48: =M49+M50-M51+M52 -> 238176.75 | N48: =N49+N50-N51+N52 -> -511683.85
...

Sheet Ratios
A1: RATIOS | D1: Société : | E1: =IF(Etatsfin!D2="","",Etatsfin!D2) -> MERIPLAST
A2: =TODAY() -> 46304 | D2: Groupe : | E2: =IF(Etatsfin!D3="","",Etatsfin!D3) -> SARL
A3: =IF(OR(Etatsfin!D1="",Etatsfin!D1="A saisir ici"),CONCATENATE(" Unité de compte : ",Etatsfin!P1),CONCATENATE(" Unité de compte : ",Etatsfin!D1)) -> Unité de compte : 000' DZD | D3: =Etatsfin!D5 -> 39417 | E3: =Etatsfin!E5 -> 39783 | F3: =Etatsfin!F5 -> 40178 | G3: =Etatsfin!G5 -> 40543
A4: (Exploitation)
A5: =CONCATENATE(" Rappel du Chiffre d'Affaires (en ",Etatsfin!O1,")") -> Rappel du Chiffre d'Affaires (en 000' DZD) | D5: =Saisie!E120 -> 416226.91 | E5: =Saisie!F120 -> 717966.67 | F5: =Saisie!G120 -> 907795.82 | G5: =Saisie!H120 -> 1616204.7
A6: Evolution du CA (annualisée) | D6: =IF(OR(Saisie!D120=0,Saisie!E120=0,Etatsfin!D6=0),"n/d ",((Saisie!E120/Saisie!D120)*(1/Etatsfin!D6))-1) -> n/d | E6: =IF(OR(Saisie!E120=0,Saisie!F120=0,Etatsfin!E6=0),"n/d ",((Saisie!F120/Saisie!E120)*(1/Etatsfin!E6))-1) -> 0.72022759 | F6: =IF(OR(Saisie!F120=0,Saisie!G120=0,Etatsfin!F6=0),"n/d ",((Saisie!G120/Saisie!F120)*(1/Etatsfin!F6))-1) -> 0.16836802 | G6: =IF(OR(Saisie!G120=0,Saisie!H120=0,Etatsfin!G6=0),"n/d ",((Saisie!H120/Saisie!G120)*(1/Etatsfin!G6))-1) -> 0.78036144
A7: % des exportations | D7: =IF(Saisie!E120=0,"n/d ",Saisie!E121/Saisie!E120) -> 0 | E7: =IF(Saisie!F120=0,"n/d ",Saisie!F121/Saisie!F120) -> 0 | F7: =IF(Saisie!G120=0,"n/d ",Saisie!G121/Saisie!G120) -> 0 | G7: =IF(Saisie!H120=0,"n/d ",Saisie!H121/Saisie!H120) -> 0
A9: Marge commerciale / CA | D9: =IF(D5=0,"n/d",Saisie!E133/D5) -> 0.12251641 | E9: =IF(E5=0,"n/d",Saisie!F133/E5) -> 0.10949735 | F9: =IF(F5=0,"n/d",Saisie!G133/F5) -> 0.17789395 | G9: =IF(G5=0,"n/d",Saisie!H133/G5) -> 0.14723784
A10: EBE / CA | D10: =IF(D5=0,"n/d",Saisie!E148/D5) -> 0.071688983 | E10: =IF(E5=0,"n/d",Saisie!F148/E5) -> 0.062834775 | F10: =IF(F5=0,"n/d",Saisie!G148/F5) -> 0.094057213 | G10: =IF(G5=0,"n/d",Saisie!H148/G5) -> 0.070562816
A11: Résultat économique / CA | D11: =IF(D5=0,"n/d ", Saisie!E155/D5) -> 0.044328052 | E11: =IF(E5=0,"n/d ", Saisie!F155/E5) -> 0.035864891 | F11: =IF(F5=0,"n/d ", Saisie!G155/F5) -> 0.071057442 | G11: =IF(G5=0,"n/d ", Saisie!H155/G5) -> 0.054379601
A12: Achats & Sous-traitance / CA | D12: =IF(D5=0,"n/d ",Saisie!E126/D5) -> 0.87748359 | E12: =IF(E5=0,"n/d ",Saisie!F126/E5) -> 0.89050265 | F12: =IF(F5=0,"n/d ",Saisie!G126/F5) -> 0.84354746 | G12: =IF(G5=0,"n/d ",Saisie!H126/G5) -> 0.85328948
A13: Charges de personnel / CA | D13: =IF(D5=0,"n/d ",Saisie!E134/D5) -> 0.015665049 | E13: =IF(E5=0,"n/d ",Saisie!F134/E5) -> 0.01764508 | F13: =IF(F5=0,"n/d ",Saisie!G134/F5) -> 0.036177278 | G13: =IF(G5=0,"n/d ",Saisie!H134/G5) -> 0.033419007
A14: Autres charges / CA | D14: =IF(D5=0,"n/d ",Saisie!E140/D5) -> 0.035162376 | E14: =IF(E5=0,"n/d ",Saisie!F140/E5) -> 0.029017492 | F14: =IF(F5=0,"n/d ",Saisie!G140/F5) -> 0.047659456 | G14: =IF(G5=0,"n/d ",Saisie!H140/G5) -> 0.043256021
A15: (Rentabilité)
A16: Résultat net / CA | D16: =IF(D5=0,"n/d",Saisie!E183/D5) -> 0.02162392 | E16: =IF(E5=0,"n/d",Saisie!F183/E5) -> 0.02560429 | F16: =IF(F5=0,"n/d",Saisie!G183/F5) -> 0.023538694 | G16: =IF(G5=0,"n/d",Saisie!H183/G5) -> 0.017180167
A17: Résultat net / Fonds Propres | D17: =IF(OR(Etatsfin!J8=0,Etatsfin!D6=0),"n/d",Etatsfin!D73/Etatsfin!D6/Etatsfin!J8) -> 0.035053453 | E17: =IF(OR(Etatsfin!K8=0,Etatsfin!E6=0),"n/d",Etatsfin!E73/Etatsfin!E6/Etatsfin!K8) -> 0.17381837 | F17: =IF(OR(Etatsfin!L8=0,Etatsfin!F6=0),"n/d",Etatsfin!F73/Etatsfin!F6/Etatsfin!L8) -> 0.15570346 | G17: =IF(OR(Etatsfin!M8=0,Etatsfin!G6=0),"n/d",Etatsfin!G73/Etatsfin!G6/Etatsfin!M8) -> 0.17680814
A18: Résultat net / Total Actif | D18: =IF(OR(Etatsfin!D31=0,Etatsfin!D6=0),"n/d ",(Etatsfin!D73/Etatsfin!D6)/Etatsfin!D31) -> 0.0079374145 | E18: =IF(OR(Etatsfin!E31=0,Etatsfin!E6=0),"n/d ",(Etatsfin!E73/Etatsfin!E6)/Etatsfin!E31) -> 0.028374982 | F18: =IF(OR(Etatsfin!F31=0,Etatsfin!F6=0),"n/d ",(Etatsfin!F73/Etatsfin!F6)/Etatsfin!F31) -> 0.02538716 | G18: =IF(OR(Etatsfin!G31=0,Etatsfin!G6=0),"n/d ",(Etatsfin!G73/Etatsfin!G6)/Etatsfin!G31) -> 0.025046892
A19: CA / Total Actif (en X) | D19: =IF(OR(Etatsfin!D31=0,Etatsfin!D6=0),"n/d ",(D5/Etatsfin!D6)/Etatsfin!D31) -> 0.3670664 | E19: =IF(OR(Etatsfin!E31=0,Etatsfin!E6=0),"n/d ",(E5/Etatsfin!E6)/Etatsfin!E31) -> 1.108212 | F19: =IF(OR(Etatsfin!F31=0,Etatsfin!F6=0),"n/d ",(F5/Etatsfin!F6)/Etatsfin!F31) -> 1.0785288 | G19: =IF(OR(Etatsfin!G31=0,Etatsfin!G6=0),"n/d ",(G5/Etatsfin!G6)/Etatsfin!G31) -> 1.4578957
A20: Total Actif / Fonds Propres (en X) | D20: =IF(OR(Etatsfin!J8=0,Etatsfin!D6=0),"n/d",Etatsfin!D31/Etatsfin!D6/Etatsfin!J8) -> 1.4720769 | E20: =IF(OR(Etatsfin!K8=0,Etatsfin!E6=0),"n/d",Etatsfin!E31/Etatsfin!E6/Etatsfin!K8) -> 6.1090243 | F20: =IF(OR(Etatsfin!L8=0,Etatsfin!F6=0),"n/d",Etatsfin!F31/Etatsfin!F6/Etatsfin!L8) -> 5.6673483 | G20: =IF(OR(Etatsfin!M8=0,Etatsfin!G6=0),"n/d",Etatsfin!G31/Etatsfin!G6/Etatsfin!M8) -> 7.0590852
A21: Tx de distrib. dividendes [=Dividendes au titre de n / RN(n)] | D21: =IF(Etatsfin!J68=0,"n/d ",(Etatsfin!J68/Etatsfin!J12)) -> n/d | E21: =IF(Etatsfin!K68=0,"n/d ",(Etatsfin!K68/Etatsfin!K12)) -> n/d | F21: =IF(Etatsfin!L68=0,"n/d ",(Etatsfin!L68/Etatsfin!L12)) -> n/d | G21: =IF(Etatsfin!M68=0,"n/d ",(Etatsfin!M68/Etatsfin!M12)) -> n/d
A22: (Dette)
A23: Résultat financier retraité / CA | D23: =IF(D5=0,"n/d",(Saisie!E156-Saisie!E161+Saisie!E158/3)/D5) -> 0.012855387 | E23: =IF(E5=0,"n/d",(Saisie!F156-Saisie!F161+Saisie!F158/3)/E5) -> 0.0099385176 | F23: =IF(F5=0,"n/d",(Saisie!G156-Saisie!G161+Saisie!G158/3)/F5) -> 0.025691839 | G23: =IF(G5=0,"n/d",(Saisie!H156-Saisie!H161+Saisie!H158/3)/G5) -> 0.032874261
A24: EBE / Résultat fin. retraité | D24: =IF((Saisie!E156+Saisie!E158/3-Saisie!E161=0),"n/d",Saisie!E148/(Saisie!E156+Saisie!E158/3-Saisie!E161)) -> 5.5765714 | E24: =IF((Saisie!F156+Saisie!F158/3-Saisie!F161=0),"n/d",Saisie!F148/(Saisie!F156+Saisie!F158/3-Saisie!F161)) -> 6.3223488 | F24: =IF((Saisie!G156+Saisie!G158/3-Saisie!G161=0),"n/d",Saisie!G148/(Saisie!G156+Saisie!G158/3-Saisie!G161)) -> 3.6609762 | G24: =IF((Saisie!H156+Saisie!H158/3-Saisie!H161=0),"n/d",Saisie!H148/(Saisie!H156+Saisie!H158/3-Saisie!H161)) -> 2.1464457
A25: EBE - Invest. indust. / Résultat financier retraité | D25: =IF(Etatsfin!J43=0,"n/d ",(Etatsfin!D56-Etatsfin!J56)/Etatsfin!J43) -> -8.5331589 | E25: =IF(Etatsfin!K43=0,"n/d ",(Etatsfin!E56-Etatsfin!K56)/Etatsfin!K43) -> -2.2872787 | F25: =IF(Etatsfin!L43=0,"n/d ",(Etatsfin!F56-Etatsfin!L56)/Etatsfin!L43) -> 3.1401559 | G25: =IF(Etatsfin!M43=0,"n/d ",(Etatsfin!G56-Etatsfin!M56)/Etatsfin!M43) -> 1.6466192
A27: EBE / Service de la dette (=frais fin.+échéance DLMT+ann.cdt-bail) | D27: =IF(OR(Etatsfin!D63+Saisie!D192+Etatsfin!D64=0,Saisie!E192=0,Etatsfin!D6>1.003,Etatsfin!D6<1),"n/d ",Etatsfin!D56/(Etatsfin!D63+Saisie!E192+Etatsfin!D64)) -> n/d | E27: =IF(OR(Etatsfin!E63+Saisie!E192+Etatsfin!E64=0,Saisie!F192=0,Etatsfin!E6>1.003,Etatsfin!E6<1),"n/d ",Etatsfin!E56/(Etatsfin!E63+Saisie!F192+Etatsfin!E64)) -> n/d | F27: =IF(OR(Etatsfin!F63+Saisie!F192+Etatsfin!F64=0,Saisie!G192=0,Etatsfin!F6>1.003,Etatsfin!F6<1),"n/d ",Etatsfin!F56/(Etatsfin!F63+Saisie!G192+Etatsfin!F64)) -> n/d | G27: =IF(OR(Etatsfin!G63+Saisie!G192+Etatsfin!G64=0,Saisie!H192=0,Etatsfin!G6>1.003,Etatsfin!G6<1),"n/d ",Etatsfin!G56/(Etatsfin!G63+Saisie!H192+Etatsfin!G64)) -> n/d
A28: EBE - Invest. indust. / Service de la dette | D28: =IF(OR(Etatsfin!D63+Saisie!D192+Etatsfin!D64=0,Saisie!E192=0,Etatsfin!D6>1.003,Etatsfin!D6<1),"n/d ",(Etatsfin!D56-Etatsfin!J56)/(Etatsfin!D63+Saisie!E192+Etatsfin!D64)) -> n/d | E28: =IF(OR(Etatsfin!E63+Saisie!E192+Etatsfin!E64=0,Saisie!F192=0,Etatsfin!E6>1.003,Etatsfin!E6<1),"n/d ",(Etatsfin!E56-Etatsfin!K56)/(Etatsfin!E63+Saisie!F192+Etatsfin!E64)) -> n/d | F28: =IF(OR(Etatsfin!F63+Saisie!F192+Etatsfin!F64=0,Saisie!G192=0,Etatsfin!F6>1.003,Etatsfin!F6<1),"n/d ",(Etatsfin!F56-Etatsfin!L56)/(Etatsfin!F63+Saisie!G192+Etatsfin!F64)) -> n/d | G28: =IF(OR(Etatsfin!G63+Saisie!G192+Etatsfin!G64=0,Saisie!H192=0,Etatsfin!G6>1.003,Etatsfin!G6<1),"n/d ",(Etatsfin!G56-Etatsfin!M56)/(Etatsfin!G63+Saisie!H192+Etatsfin!G64)) -> n/d
A29: CFEN+(Frais fin.+1/3 Ann.cdt-bail) - Inv. ind. / Serv. de la dette | D29: =IF(OR(Etatsfin!D63+Saisie!D192+Etatsfin!D64=0,Saisie!E192=0,Etatsfin!D6>1.003,Etatsfin!D6<1),"n/d ",(Etatsfin!J54+(Etatsfin!D63+(Etatsfin!D64/3))-Etatsfin!J56)/(Etatsfin!D63+Saisie!E192+Etatsfin!D64)) -> n/d | E29: =IF(OR(Etatsfin!E63+Saisie!E192+Etatsfin!E64=0,Saisie!F192=0,Etatsfin!E6>1.003,Etatsfin!E6<1),"n/d ",(Etatsfin!K54+(Etatsfin!E63+(Etatsfin!E64/3))-Etatsfin!K56)/(Etatsfin!E63+Saisie!F192+Etatsfin!E64)) -> n/d | F29: =IF(OR(Etatsfin!F63+Saisie!F192+Etatsfin!F64=0,Saisie!G192=0,Etatsfin!F6>1.003,Etatsfin!F6<1),"n/d ",(Etatsfin!L54+(Etatsfin!F63+(Etatsfin!F64/3))-Etatsfin!L56)/(Etatsfin!F63+Saisie!G192+Etatsfin!F64)) -> n/d | G29: =IF(OR(Etatsfin!G63+Saisie!G192+Etatsfin!G64=0,Saisie!H192=0,Etatsfin!G6>1.003,Etatsfin!G6<1),"n/d ",(Etatsfin!M54+(Etatsfin!G63+(Etatsfin!G64/3))-Etatsfin!M56)/(Etatsfin!G63+Saisie!H192+Etatsfin!G64)) -> n/d
A31: =CONCATENATE(" Dettes financières totales (en ",Etatsfin!O1,")") -> Dettes financières totales (en 000' DZD) | D31: =Etatsfin!J17+Etatsfin!J29+Etatsfin!J34+(2*Etatsfin!J35/3) -> 135768.57 | E31: =Etatsfin!K17+Etatsfin!K29+Etatsfin!K34+(2*Etatsfin!K35/3) -> 318123.7 | F31: =Etatsfin!L17+Etatsfin!L29+Etatsfin!L34+(2*Etatsfin!L35/3) -> 301703.26 | G31: =Etatsfin!M17+Etatsfin!M29+Etatsfin!M34+(2*Etatsfin!M35/3) -> 583688.85
A32: =CONCATENATE(" Dettes financières totales nettes (en ",Etatsfin!O1,")") -> Dettes financières totales nettes (en 000' DZD) | D32: =D31-Etatsfin!D27-Etatsfin!D28 -> 105364.63 | E32: =E31-Etatsfin!E27-Etatsfin!E28 -> 191703.74 | F32: =F31-Etatsfin!F27-Etatsfin!F28 -> 278975.2 | G32: =G31-Etatsfin!G27-Etatsfin!G28 -> 479069.15
A33: Dettes financières Court Terme (yc part CT de la Dette LT) | D33: =Saisie!E113+Saisie!E192 -> 36801.173 | E33: =Saisie!F113+Saisie!F192 -> 188896.56 | F33: =Saisie!G113+Saisie!G192 -> 167884.05 | G33: =Saisie!H113+Saisie!H192 -> 451915.46
A34: Dettes financières MLT (yc part en capital du CB et hors bilan) | D34: =Saisie!E86-Saisie!E90+2/3*(Saisie!E116)+Saisie!E115 -> 45584 | E34: =Saisie!F86-Saisie!F90+2/3*(Saisie!F116)+Saisie!F115 -> 50953.402 | F34: =Saisie!G86-Saisie!G90+2/3*(Saisie!G116)+Saisie!G115 -> 61088.814 | G34: =Saisie!H86-Saisie!H90+2/3*(Saisie!H116)+Saisie!H115 -> 59043.006
A36: Dettes financières totales / Fonds propres | D36: =IF(Etatsfin!J8=0,"n/d",D31/Etatsfin!J8) -> 1.5863051 | E36: =IF(Etatsfin!K8=0,"n/d",E31/Etatsfin!K8) -> 3.0162192 | F36: =IF(Etatsfin!L8=0,"n/d",F31/Etatsfin!L8) -> 2.3790958 | G36: =IF(Etatsfin!M8=0,"n/d",G31/Etatsfin!M8) -> 3.7167205
A37: Dettes financières totales nettes / Fonds propres | D37: =IF(Etatsfin!J8=0,"n/d",D32/Etatsfin!J8) -> 1.2310688 | E37: =IF(Etatsfin!K8=0,"n/d",E32/Etatsfin!K8) -> 1.8175964 | F37: =IF(Etatsfin!L8=0,"n/d",F32/Etatsfin!L8) -> 2.1998726 | G37: =IF(Etatsfin!M8=0,"n/d",G32/Etatsfin!M8) -> 3.0505399
A38: Dettes fin. tot. / F. propres nets d'incorporels (=Gross Gearing) | D38: =IF((Etatsfin!J8-Etatsfin!D15-Etatsfin!D17)=0,"n/d ",D31/(Etatsfin!J8-Etatsfin!D15-Etatsfin!D17)) -> 1.5863051 | E38: =IF((Etatsfin!K8-Etatsfin!E15-Etatsfin!E17)=0,"n/d ",E31/(Etatsfin!K8-Etatsfin!E15-Etatsfin!E17)) -> 3.0173993 | F38: =IF((Etatsfin!L8-Etatsfin!F15-Etatsfin!F17)=0,"n/d ",F31/(Etatsfin!L8-Etatsfin!F15-Etatsfin!F17)) -> 2.3793685 | G38: =IF((Etatsfin!M8-Etatsfin!G15-Etatsfin!G17)=0,"n/d ",G31/(Etatsfin!M8-Etatsfin!G15-Etatsfin!G17)) -> 3.7266674
A39: Dettes fin. tot. nettes / F. prop. nets d'incorporels (=Net Gearing) | D39: =IF((Etatsfin!J8-Etatsfin!D15-Etatsfin!D17)=0,"n/d ",D32/(Etatsfin!J8-Etatsfin!D15-Etatsfin!D17)) -> 1.2310688 | E39: =IF((Etatsfin!K8-Etatsfin!E15-Etatsfin!E17)=0,"n/d ",E32/(Etatsfin!K8-Etatsfin!E15-Etatsfin!E17)) -> 1.8183076 | F39: =IF((Etatsfin!L8-Etatsfin!F15-Etatsfin!F17)=0,"n/d ",F32/(Etatsfin!L8-Etatsfin!F15-Etatsfin!F17)) -> 2.2001248 | G39: =IF((Etatsfin!M8-Etatsfin!G15-Etatsfin!G17)=0,"n/d ",G32/(Etatsfin!M8-Etatsfin!G15-Etatsfin!G17)) -> 3.0587039
A40: Dettes totales / F. prop. nets d'incorporels (=Leverage) | D40: =IF((Etatsfin!J8-Etatsfin!D15-Etatsfin!D17)=0,"n/d ",(D31+Etatsfin!J23-Etatsfin!J29)/(Etatsfin!J8-Etatsfin!D15-Etatsfin!D17)) -> 3.4162306 | E40: =IF((Etatsfin!K8-Etatsfin!E15-Etatsfin!E17)=0,"n/d ",(E31+Etatsfin!K23-Etatsfin!K29)/(Etatsfin!K8-Etatsfin!E15-Etatsfin!E17)) -> 5.1277668 | F40: =IF((Etatsfin!L8-Etatsfin!F15-Etatsfin!F17)=0,"n/d ",(F31+Etatsfin!L23-Etatsfin!L29)/(Etatsfin!L8-Etatsfin!F15-Etatsfin!F17)) -> 5.2211975 | G40: =IF((Etatsfin!M8-Etatsfin!G15-Etatsfin!G17)=0,"n/d ",(G31+Etatsfin!M23-Etatsfin!M29)/(Etatsfin!M8-Etatsfin!G15-Etatsfin!G17)) -> 6.1263782
A42: Dettes financières totales / EBE (en années) | D42: =IF(Etatsfin!D56=0,"n/d",Etatsfin!D6*(D31/Etatsfin!D56)) -> 13.650166 | E42: =IF(Etatsfin!E56=0,"n/d",Etatsfin!E6*(E31/Etatsfin!E56)) -> 7.0709847 | F42: =IF(Etatsfin!F56=0,"n/d",Etatsfin!F6*(F31/Etatsfin!F56)) -> 3.8238772 | G42: =IF(Etatsfin!G56=0,"n/d",Etatsfin!G6*(G31/Etatsfin!G56)) -> 5.1181044
A43: Dettes financières totales nettes / EBE (en années) | D43: =IF(Etatsfin!D56=0,"n/d ",Etatsfin!D6*(D32/Etatsfin!D56)) -> 10.593355 | E43: =IF(Etatsfin!E56=0,"n/d ",Etatsfin!E6*(E32/Etatsfin!E56)) -> 4.2610287 | F43: =IF(Etatsfin!F56=0,"n/d ",Etatsfin!F6*(F32/Etatsfin!F56)) -> 3.5358151 | G43: =IF(Etatsfin!G56=0,"n/d ",Etatsfin!G6*(G32/Etatsfin!G56)) -> 4.2007414
A44: Dettes financières MLT / EBE (en années) | D44: =IF(OR(Saisie!D148=0,Etatsfin!D56=0),"n/d ",Etatsfin!D6*(D34/Saisie!E148)) -> n/d | E44: =IF(OR(Saisie!E148=0,Etatsfin!E56=0),"n/d ",Etatsfin!E6*(E34/Saisie!F148)) -> 1.1325491 | F44: =IF(OR(Saisie!F148=0,Etatsfin!F56=0),"n/d ",Etatsfin!F6*(F34/Saisie!G148)) -> 0.77425789 | G44: =IF(OR(Saisie!G148=0,Etatsfin!G56=0),"n/d ",Etatsfin!G6*(G34/Saisie!H148)) -> 0.5177215
A45: Dettes financières totales / CFEN (en années) | D45: =IF(OR(Etatsfin!J54<0,Etatsfin!J54=0),"n/d",Etatsfin!D6*D31/Etatsfin!J54) -> n/d | E45: =IF(OR(Etatsfin!K54<0,Etatsfin!K54=0),"n/d",Etatsfin!E6*E31/Etatsfin!K54) -> n/d | F45: =IF(OR(Etatsfin!L54<0,Etatsfin!L54=0),"n/d",Etatsfin!F6*F31/Etatsfin!L54) -> n/d | G45: =IF(OR(Etatsfin!M54<0,Etatsfin!M54=0),"n/d",Etatsfin!G6*G31/Etatsfin!M54) -> n/d
...

Sheet Hypo
L1: Zone réservée.
A2: Voulez-vous des hypothèses plus détaillées que ci-dessous ? (O / N) : | H2: (En l'absence de saisie "O" ou "N", | L2: Ne rien modifier.
A3: (Pour des explications, cliquer le "bouton de dégroupage" ci-dessous à gauche) | H3: la réponse par défaut est "N") | L3: =IF(OR(G2="O",G2="Oui"),0,1) -> 1 | M3: =IF(L3=1,0,1) -> 0
A5: a) En cas de réponse négative à la question ci-dessus, l'utilisateur saisit ses hypothèses dans les cellules de
A6: cette Feuille "Hypo", sans aucune autre action particulière.
A8: b) En cas de réponse positive, l'utilisateur doit saisir 8 postes d'hypothèses (CA, Marge Commerciale, Frais de
A9: personnel, Autres charges, et EBE, ainsi que Nouveaux Emprunts à MLT, Rembts de DLMT et Investissements
A10: financiers), dans les zones Compte de Résultat et Tableau de Flux de "PrSept".
A12: Il devra alors dans "PrSept" afficher les lignes de saisie détaillée (cellules jaunes) avec les "boutons de
A13: dégroupage" (à gauche, bord du cadre). S'il ne veut pas détailler l'un de ces 8 postes, il devra quand même saisir
A14: un total de celui-ci dans une quelconque des cellules jaunes, puis le masquer à l'aide du "bouton de dégroupage".
A15: Il convient d'ailleurs de noter que l'utilisateur peut ajouter ou retirer autant de lignes de détails qu'il souhaite dans
A16: ces 8 postes, si et seulement si il en "insère" ou en "supprime" entre la première ligne et la dernière ligne
A17: existantes. (Dans ce cas, Excel met en effet automatiquement à jour tout ce qui est nécessaire.)
A19: Pour l'impression et l'affichage, l'utilisateur peut, toujours grâce aux "boutons", imprimer et/ou masquer ce qu'il
A20: souhaite : il lui incombe de régler les paramètres qui lui conviennent, puisqu' il n'a pas choisi l'option par défaut.
L23: Date: | M23: =TODAY() -> 46304 | N23: =TODAY() -> 46304
A24: Société : | B24: =IF(PrSept!B19="Saisir sur Saisie ou Etatsfin",CONCATENATE(PrSept!B19," ou PrSept"),PrSept!B19) -> MERIPLAST
A25: Groupe : | B25: =IF(PrSept!B20="Saisir sur Saisie ou Etatsfin",CONCATENATE(PrSept!B20," ou PrSept"),PrSept!B20) -> MERIPLAST | L25: Scénario : | M25: A saisir ici
E29: =PrSept!E25 -> Historique | H29: =PrSept!H25 -> Prévisions
A30: Hypothèses retenues : | E30: =PrSept!E26 -> 39783 | F30: =PrSept!F26 -> 40178 | G30: =PrSept!G26 -> 40543 | H30: =PrSept!H26 -> 40909 | I30: =PrSept!I26 -> 41275 | J30: =PrSept!J26 -> 41641 | K30: =PrSept!K26 -> 42007 | L30: =PrSept!L26 -> 42373 | ... N30: =PrSept!N26 -> 43105 | O30: Hypothèses retenues :
A31: =IF(OR(PrSept!T27<1,PrSept!T27>1.003)," (Message à effacer après lecture) La durée de l'un des exercices de l'historique n'est pas de 12 mois. Comme pour toutes les autres Feuilles, les chiffres ci-dessous exprimés en % ou en jours sont annualisés; ceux exprimés en montant ne le sont pas.","")
A32: Eléments de l'exploitation : | B32: (en %) | O32: Eléments de l'exploitation : (en %)
A33: Evolution du CA (annualisée) | E33: =PrSept!E105 -> 4.1606828 | F33: =PrSept!F105 -> 0.17156903 | G33: =PrSept!G105 -> 0.92669252 | O33: Evolution du CA (annualisée)
A34: =CONCATENATE("CA (en ",PrSept!O21,")") -> CA (en KF) | B34: (calculé) | E34: =PrSept!E104 -> 717966.67 | F34: =PrSept!F104 -> 907795.82 | G34: =PrSept!G104 -> 1616204.7 | O34: =A34 -> CA (en KF) | Q34: (calculé)
A35: Marge commerciale / CA | E35: =PrSept!E119 -> 0.10949735 | F35: =PrSept!F119 -> 0.17789395 | G35: =PrSept!G119 -> 0.14723784 | O35: Marge commerciale / CA
A36: EBE / CA | E36: =PrSept!E136 -> 0.062834775 | F36: =PrSept!F136 -> 0.094057213 | G36: =PrSept!G136 -> 0.070562816 | O36: EBE / CA
A37: Dotation aux amortiss. / Immo. d'exploitation brutes | E37: =IF(OR(PrSept!E29=0,PrSept!R27=0),"n/d ",(PrSept!E143/PrSept!R27)/PrSept!E29) -> 0.1291502 | F37: =IF(OR(PrSept!F29=0,PrSept!S27=0),"n/d ",(PrSept!F143/PrSept!S27)/PrSept!F29) -> 0.11933342 | G37: =IF(OR(PrSept!G29=0,PrSept!T27=0),"n/d ",(PrSept!G143/PrSept!T27)/PrSept!G29) -> 0.15127617 | O37: Dotation aux amortiss. / Immo. d'exploitation brutes
A38: Eléments de coût du capital : | B38: (en %) | O38: Eléments de coût du capital : (en %)
A39: Frais fi. / Dette fi. totale moyenne de l'année (hors cdt-bail) | E39: =PrSept!E16 -> 0.031355583 | F39: =PrSept!F16 -> 0.068560631 | G39: =PrSept!G16 -> 0.13383155 | O39: Frais fi. / Dette fi. totale moyenne de l'année (hors cdt-bail)
A40: Produits financiers / VMP et Disponible moyens de l'année | E40: =IF(OR((Etatsfin!D27+Etatsfin!D28+PrSept!E47=0),PrSept!R27=0,Etatsfin!D31=0,Etatsfin!J31=0),"n/d ",(PrSept!E151/PrSept!R27)/((Etatsfin!D27+Etatsfin!D28+PrSept!E47)/2)) -> 0 | F40: =IF(OR((PrSept!E47+PrSept!F47=0),PrSept!S27=0,PrSept!E49=0,PrSept!E82=0),"n/d ",(PrSept!F151/PrSept!S27)/((PrSept!E47+PrSept!F47)/2)) -> 0 | G40: =IF(OR((PrSept!F47+PrSept!G47=0),PrSept!T27=0,PrSept!F49=0,PrSept!F82=0),"n/d ",(PrSept!G151/PrSept!T27)/((PrSept!F47+PrSept!G47)/2)) -> 0.075978129 | O40: Produits financiers / VMP et Disponible moyens de l'année
A41: Taux d'IS (= IS / Résultat avant IS) | E41: =PrSept!E17 -> 0.24999982 | F41: =PrSept!F17 -> 0.24512003 | G41: =PrSept!G17 -> 0.20112084 | O41: Taux d'IS (= IS / Résultat avant IS)
A42: Tx de distrib. de dividendes [=Dividendes au titre de n / RN(n)] | E42: =IF(PrSept!E165=0,"n/d ",(PrSept!E165-PrSept!E57)/PrSept!E165) -> 9.7916411e-07 | F42: =IF(PrSept!F165=0,"n/d ",(PrSept!F165-PrSept!F57)/PrSept!F165) -> 4.225828e-06 | G42: =IF(PrSept!G165=0,"n/d ",(PrSept!G165-PrSept!G57)/PrSept!G165) -> 2.1608643e-07 | O42: Tx de distrib. de dividendes [=Dividendes au titre de n / RN(n)]
A43: Eléments de haut-de-bilan : | B43: =CONCATENATE("(en ",PrSept!O21,")") -> (en KF) | E43: =IF(OR(H41<0,I41<0,J41<0,K41<0,L41<0,M41<0,N41<0,H42<0,I42<0,J42<0,K42<0,L42<0,M42<0,N42<0),"Les 2 taux ci-dessus (IS et Divid.) doivent être >0; ceux qui sont <0 seront convertis en ''0'' pour les calculs, sauf à procéder comme indiqué en cellule R67/68 >>>","") | O43: Elémts de haut-de-bil. : | Q43: =B43 -> (en KF) | R43: =IF(E43="",""," a) Si vous souhaitez de l' IS malgré des pertes, vous pouvez considérer celui-ci comme une ''Charge hors exploitation ''cash'' '' à saisir dans cette Feuille, sur la ligne 91.")
A44: Investissement industriel | E44: =PrSept!E218 -> 61434.208 | F44: =PrSept!F218 -> 12147.064 | G44: =PrSept!G218 -> 26556.55 | O44: Invest. industr. (hors pduct° immobilisée) | R44: =IF(E43="",""," b) Si vous souhaitez des dividendes malgré des pertes, vous pouvez directement saisir ceux-ci à partir de l'année ''H'' dans le Tableau de Flux de ''PrSept'' en écrasant les formules.")
A45: Nouveaux Emprunts à LMT | E45: =IF(PrSept!E233+PrSept!E234<0,"n/d ",PrSept!E233+PrSept!E234) -> 30259.744 | F45: =IF(PrSept!F233+PrSept!F234<0,"n/d ",PrSept!F233+PrSept!F234) -> n/d | G45: =IF(PrSept!G233+PrSept!G234<0,"n/d ",PrSept!G233+PrSept!G234) -> 1043.006 | O45: Nouveaux Emprunts à LMT
A46: Remboursement de DLMT | E46: =PrSept!E234 -> 0 | F46: =PrSept!F234 -> 0 | G46: =PrSept!G234 -> 0 | O46: Remboursement de DLMT
A47: Nouveau Crédit-bail | E47: =IF(PrSept!E90-Etatsfin!J35+PrSept!E150<0,"n/d ",PrSept!E90-Etatsfin!J35+PrSept!E150) -> 0 | F47: =IF(PrSept!F90-PrSept!E90+PrSept!F150<0,"n/d ",PrSept!F90-PrSept!E90+PrSept!F150) -> 18853.378 | G47: =IF(PrSept!G90-PrSept!F90+PrSept!G150<0,"n/d ",PrSept!G90-PrSept!F90+PrSept!G150) -> n/d | O47: Nouveau Crédit-bail
A48: Annuités de crédit-bail | E48: =PrSept!E150 -> 0 | F48: =PrSept!F150 -> 2220.157 | G48: =PrSept!G150 -> 0 | O48: Annuités de crédit-bail
A49: Eléments du BFR : | B49: (en Jours) | O49: Eléments du BFR : (en Jours)
...

Sheet PrSept
A1: Reprise de données pour les Feuilles "Résumé", "PrCinq" et "Dette" (ne pas modifier) : Ne pas non plus ajouter de lignes dans, ou avant, ce bloc gris. | H1: =H26 -> 40909 | I1: =I26 -> 41275 | J1: =J26 -> 41641 | K1: =K26 -> 42007 | L1: =L26 -> 42373 | M1: =M26 -> 42739 | N1: =N26 -> 43105 | O1: Reprise de données pour la Feuille de Résumé (ne pas modifier) : Ne pas non plus ajouter de lignes dans ou avant ce bloc gris.
A2: Scénario : | B2: CA : | H2: =H104 -> 1616204.7 | I2: =I104 -> 1616204.7 | J2: =J104 -> 1616204.7 | K2: =K104 -> 1616204.7 | L2: =L104 -> 1616204.7 | M2: =M104 -> 1616204.7 | N2: =N104 -> 1616204.7 | P2: CA :
A3: =M20 -> A saisir sur Hypo | B3: EBE : | H3: =H135 -> 0 | I3: =I135 -> 0 | J3: =J135 -> 0 | K3: =K135 -> 0 | L3: =L135 -> 0 | M3: =M135 -> 0 | N3: =N135 -> 0 | P3: EBE :
B4: Dettes financières totales : | H4: =H287 -> 131773.39 | I4: =I287 -> 131773.39 | J4: =J287 -> 131773.39 | K4: =K287 -> 131773.39 | L4: =L287 -> 131773.39 | M4: =M287 -> 131773.39 | N4: =N287 -> 131773.39 | P4: Dettes financières totales :
B5: Croissance du CA (%) : | H5: =H105 -> 0 | I5: =I105 -> 0 | J5: =J105 -> 0 | K5: =K105 -> 0 | L5: =L105 -> 0 | M5: =M105 -> 0 | N5: =N105 -> 0 | P5: Croissance du CA (%) :
B6: EBE / CA (%) : | H6: =H272 -> 0 | I6: =I272 -> 0 | J6: =J272 -> 0 | K6: =K272 -> 0 | L6: =L272 -> 0 | M6: =M272 -> 0 | N6: =N272 -> 0 | P6: EBE / CA (%) :
B7: EBE / Résultat financier retraité (%) : | H7: =H281 -> n/d | I7: =I281 -> n/d | J7: =J281 -> n/d | K7: =K281 -> n/d | L7: =L281 -> n/d | M7: =M281 -> n/d | N7: =N281 -> n/d | P7: EBE / Résultat financier retraité (%) :
B8: Dettes financières totales / EBE (années) : | H8: =H293 -> n/d | I8: =I293 -> n/d | J8: =J293 -> n/d | K8: =K293 -> n/d | L8: =L293 -> n/d | M8: =M293 -> n/d | N8: =N293 -> n/d | P8: Dettes financières totales / EBE (années) :
